<?xml version="1.0"?>
<robot xmlns:xacro="http://www.ros.org/wiki/xacro">
    <xacro:macro name="wheel" params="parent prefix reflect offset_x offset_z">
        <link name="${prefix}_wheel">
            <visual>
                <geometry>
                    <cylinder radius="0.05" length="0.04" />
                </geometry>
                <material name="blue" />
            </visual>
        </link>

        <joint name="${prefix}_wheel_to_lower_suspension" type="continuous">
            <parent link="${parent}" />
            <child link="${prefix}_wheel" />
            <axis xyz="0 0 ${reflect*1}" />
            <origin xyz="${offset_x} ${reflect*0.025} ${offset_z}" rpy="${reflect*-pi/2} 0 0" />
        </joint>


    </xacro:macro>

</robot>
